2020-12-15 01:58:12,794 - LoggerFrameworkApp - INFO - Sistema inicializado.....
2020-12-15 01:58:12,794 - LoggerFrameworkApp - INFO - objeto da classe TestMyLogger criado...
2020-12-15 01:58:12,794 - LoggerFrameworkApp - ERROR - <type 'exceptions.Exception'>
Traceback (most recent call last):
  File "/opt/projetos/Django/logger_framework/logger_multiple_modules/test/TestMyLogger.py", line 50, in <module>
    t1.do("faz algum trein", 124)
TypeError: do() takes exactly 2 arguments (3 given)
2020-12-15 01:59:35,501 - LoggerFrameworkApp - INFO - Sistema inicializado.....
2020-12-15 01:59:35,501 - LoggerFrameworkApp - INFO - objeto da classe TestMyLogger criado...
2020-12-15 01:59:35,501 - LoggerFrameworkApp - ERROR - <type 'exceptions.Exception'>
Traceback (most recent call last):
  File "/opt/projetos/Django/logger_framework/logger_multiple_modules/test/TestMyLogger.py", line 49, in <module>
    t1.do("faz algum trein", 124)
TypeError: do() takes exactly 2 arguments (3 given)
2020-12-15 02:00:01,951 - LoggerFrameworkApp - INFO - Sistema inicializado.....
2020-12-15 02:00:01,951 - LoggerFrameworkApp - INFO - objeto da classe TestMyLogger criado...
2020-12-15 02:00:01,951 - LoggerFrameworkApp - INFO - parametro do metodo do() : faz algum trein 
2020-12-15 02:00:01,952 - LoggerFrameworkApp - INFO - EXECUTANDO METODO DO()
2020-12-15 03:54:19,353 - LoggerFrameworkApp - INFO - Sistema inicializado.....
2020-12-15 03:54:19,364 - LoggerFrameworkApp - INFO - objeto da classe TestMyLogger criado...
2020-12-15 03:54:19,364 - LoggerFrameworkApp - ERROR - <attribute 'message' of 'exceptions.BaseException' objects>
Traceback (most recent call last):
  File "/opt/projetos/Django/logger_framework/logger_multiple_modules/test/TestMyLogger.py", line 49, in <module>
    t1.do("faz algum trein", 236)
TypeError: do() takes exactly 2 arguments (3 given)
2020-12-15 03:55:27,844 - LoggerFrameworkApp - INFO - Sistema inicializado.....
2020-12-15 03:55:27,845 - LoggerFrameworkApp - INFO - objeto da classe TestMyLogger criado...
2020-12-15 03:55:27,845 - LoggerFrameworkApp - ERROR - Error on processing some task <attribute 'message' of 'exceptions.BaseException' objects>
Traceback (most recent call last):
  File "/opt/projetos/Django/logger_framework/logger_multiple_modules/test/TestMyLogger.py", line 49, in <module>
    t1.do("faz algum trein", 236)
TypeError: do() takes exactly 2 arguments (3 given)
